Workbook

Sheet Sheet1
B1: 1 | C1: 2 | D1: 3 | E1: 4 | F1: 5 | G1: 6 | H1: 7 | I1: 8 | J1: 9 | K1: 10 | L1: 11 | M1: 12
A2: A | B2: 0.093 | C2: 0.097 | D2: 0.094 | E2: 0.093 | F2: 0.089 | G2: 0.093 | N2: 632 | O2: unblanked, not path corrected
A3: B | B3: 0.098 | C3: 0.092 | D3: 0.093 | E3: 0.089 | F3: 0.117 | G3: 0.094 | N3: 632
A4: C | B4: 0.093 | C4: 0.103 | D4: 0.092 | E4: 0.092 | F4: 0.094 | G4: 0.091 | N4: 632
A5: D | B5: 0.092 | C5: 0.105 | D5: 0.091 | N5: 632
A6: E | B6: 0.186 | C6: 0.086 | D6: 0.088 | N6: 632
A7: F | B7: 0.09 | C7: 0.09 | D7: 0.098 | N7: 632
A8: G | B8: 0.128 | C8: 0.088 | D8: 0.09 | N8: 632
A9: H | B9: 0.089 | C9: 0.091 | D9: 0.091 | N9: 632
B11: 1 | C11: 2 | D11: 3 | E11: 4 | F11: 5 | G11: 6 | H11: 7 | I11: 8 | J11: 9 | K11: 10 | L11: 11 | M11: 12
A12: A | B12: 0.091 | C12: 0.095 | D12: 0.091 | E12: 0.092 | F12: 0.088 | G12: 0.091 | N12: 649 | O12: unblanked, not path corrected
A13: B | B13: 0.096 | C13: 0.089 | D13: 0.092 | E13: 0.088 | F13: 0.116 | G13: 0.093 | N13: 649
A14: C | B14: 0.091 | C14: 0.1 | D14: 0.091 | E14: 0.089 | F14: 0.092 | G14: 0.089 | N14: 649
A15: D | B15: 0.09 | C15: 0.103 | D15: 0.09 | N15: 649
A16: E | B16: 0.185 | C16: 0.085 | D16: 0.087 | N16: 649
A17: F | B17: 0.088 | C17: 0.087 | D17: 0.097 | N17: 649
A18: G | B18: 0.125 | C18: 0.086 | D18: 0.089 | N18: 649
A19: H | B19: 0.089 | C19: 0.089 | D19: 0.09 | N19: 649
B21: 1 | C21: 2 | D21: 3 | E21: 4 | F21: 5 | G21: 6 | H21: 7 | I21: 8 | J21: 9 | K21: 10 | L21: 11 | M21: 12
A22: A | B22: 0.09 | C22: 0.093 | D22: 0.09 | E22: 0.092 | F22: 0.087 | G22: 0.09 | N22: 665 | O22: unblanked, not path corrected
A23: B | B23: 0.095 | C23: 0.088 | D23: 0.092 | E23: 0.088 | F23: 0.116 | G23: 0.093 | N23: 665
A24: C | B24: 0.089 | C24: 0.099 | D24: 0.091 | E24: 0.087 | F24: 0.091 | G24: 0.087 | N24: 665
A25: D | B25: 0.088 | C25: 0.102 | D25: 0.089 | N25: 665
A26: E | B26: 0.185 | C26: 0.084 | D26: 0.085 | N26: 665
A27: F | B27: 0.088 | C27: 0.086 | D27: 0.095 | N27: 665
A28: G | B28: 0.123 | C28: 0.086 | D28: 0.087 | N28: 665
A29: H | B29: 0.088 | C29: 0.088 | D29: 0.09 | N29: 665
B31: 1 | C31: 2 | D31: 3 | E31: 4 | F31: 5 | G31: 6 | H31: 7 | I31: 8 | J31: 9 | K31: 10 | L31: 11 | M31: 12
A32: A | B32: 0.089 | C32: 0.092 | D32: 0.09 | E32: 0.089 | F32: 0.085 | G32: 0.089 | N32: 696 | O32: unblanked, not path corrected
A33: B | B33: 0.094 | C33: 0.088 | D33: 0.089 | E33: 0.087 | F33: 0.114 | G33: 0.09 | N33: 696
A34: C | B34: 0.088 | C34: 0.097 | D34: 0.09 | E34: 0.087 | F34: 0.09 | G34: 0.087 | N34: 696
A35: D | B35: 0.087 | C35: 0.1 | D35: 0.088 | N35: 696
A36: E | B36: 0.185 | C36: 0.083 | D36: 0.083 | N36: 696
A37: F | B37: 0.087 | C37: 0.086 | D37: 0.091 | N37: 696
A38: G | B38: 0.12 | C38: 0.086 | D38: 0.084 | N38: 696
A39: H | B39: 0.086 | C39: 0.086 | D39: 0.088 | N39: 696
B41: 1 | C41: 2 | D41: 3 | E41: 4 | F41: 5 | G41: 6 | H41: 7 | I41: 8 | J41: 9 | K41: 10 | L41: 11 | M41: 12
A42: A | B42: 0.092 | C42: 0.092 | D42: 0.09 | E42: 0.096 | F42: 0.098 | G42: 0.092 | N42: Read 1:977 [Test] | O42: path test
A43: B | B43: 0.108 | C43: 0.097 | D43: 0.098 | E43: 0.096 | F43: 0.094 | G43: 0.099 | N43: Read 1:977 [Test]
A44: C | B44: 0.101 | C44: 0.105 | D44: 0.097 | E44: 0.145 | F44: 0.095 | G44: 0.093 | N44: Read 1:977 [Test]
...

Sheet Read 1
C1: 1 | D1: 2 | E1: 3 | F1: 4 | G1: 5 | H1: 6 | I1: 7 | J1: 8 | K1: 9 | L1: 10 | M1: 11 | N1: 12
B2: A | C2: 0.089 | D2: 0.091 | E2: 0.091 | F2: 0.122 | G2: 0.126 | H2: 0.11 | O2: Read 1:632
B3: B | C3: 0.136 | D3: 0.117 | E3: 0.127 | F3: 0.121 | G3: 0.121 | H3: 0.125 | O3: Read 1:632
B4: C | C4: 0.138 | D4: 0.126 | E4: 0.119 | F4: 0.171 | G4: 0.126 | H4: 0.123 | O4: Read 1:632
B5: D | C5: 0.115 | D5: 0.128 | E5: 0.117 | O5: Read 1:632
B6: E | C6: 0.167 | D6: 0.144 | E6: 0.115 | O6: Read 1:632
B7: F | C7: 0.11 | D7: 0.113 | E7: 0.116 | O7: Read 1:632
B8: G | C8: 0.162 | D8: 0.124 | E8: 0.119 | O8: Read 1:632
B9: H | C9: 0.112 | D9: 0.113 | E9: 0.118 | O9: Read 1:632
C11: 1 | D11: 2 | E11: 3 | F11: 4 | G11: 5 | H11: 6 | I11: 7 | J11: 8 | K11: 9 | L11: 10 | M11: 11 | N11: 12
B12: A | C12: 0.087 | D12: 0.089 | E12: 0.088 | F12: 0.114 | G12: 0.117 | H12: 0.103 | O12: Read 1:649
B13: B | C13: 0.128 | D13: 0.11 | E13: 0.121 | F13: 0.11 | G13: 0.118 | H13: 0.123 | O13: Read 1:649
B14: C | C14: 0.133 | D14: 0.121 | E14: 0.116 | F14: 0.17 | G14: 0.122 | H14: 0.117 | O14: Read 1:649
B15: D | C15: 0.11 | D15: 0.123 | E15: 0.113 | O15: Read 1:649
B16: E | C16: 0.157 | D16: 0.132 | E16: 0.108 | O16: Read 1:649
B17: F | C17: 0.106 | D17: 0.109 | E17: 0.114 | O17: Read 1:649
B18: G | C18: 0.151 | D18: 0.118 | E18: 0.113 | O18: Read 1:649
B19: H | C19: 0.106 | D19: 0.105 | E19: 0.111 | O19: Read 1:649
C21: 1 | D21: 2 | E21: 3 | F21: 4 | G21: 5 | H21: 6 | I21: 7 | J21: 8 | K21: 9 | L21: 10 | M21: 11 | N21: 12
B22: A | C22: 0.086 | D22: 0.088 | E22: 0.087 | F22: 0.148 | G22: 0.155 | H22: 0.127 | O22: Read 1:665
B23: B | C23: 0.185 | D23: 0.141 | E23: 0.17 | F23: 0.148 | G23: 0.174 | H23: 0.171 | O23: Read 1:665
B24: C | C24: 0.204 | D24: 0.163 | E24: 0.163 | F24: 0.216 | G24: 0.181 | H24: 0.169 | O24: Read 1:665
B25: D | C25: 0.149 | D25: 0.187 | E25: 0.157 | O25: Read 1:665
B26: E | C26: 0.185 | D26: 0.15 | E26: 0.133 | O26: Read 1:665
B27: F | C27: 0.133 | D27: 0.146 | E27: 0.144 | O27: Read 1:665
B28: G | C28: 0.203 | D28: 0.168 | E28: 0.15 | O28: Read 1:665
B29: H | C29: 0.132 | D29: 0.134 | E29: 0.145 | O29: Read 1:665
C31: 1 | D31: 2 | E31: 3 | F31: 4 | G31: 5 | H31: 6 | I31: 7 | J31: 8 | K31: 9 | L31: 10 | M31: 11 | N31: 12
B32: A | C32: 0.085 | D32: 0.087 | E32: 0.087 | F32: 0.09 | G32: 0.09 | H32: 0.086 | O32: Read 1:696
B33: B | C33: 0.097 | D33: 0.092 | E33: 0.093 | F33: 0.091 | G33: 0.092 | H33: 0.1 | O33: Read 1:696
B34: C | C34: 0.097 | D34: 0.098 | E34: 0.092 | F34: 0.149 | G34: 0.093 | H34: 0.092 | O34: Read 1:696
B35: D | C35: 0.088 | D35: 0.089 | E35: 0.089 | O35: Read 1:696
B36: E | C36: 0.135 | D36: 0.115 | E36: 0.089 | O36: Read 1:696
B37: F | C37: 0.092 | D37: 0.089 | E37: 0.093 | O37: Read 1:696
B38: G | C38: 0.118 | D38: 0.091 | E38: 0.088 | O38: Read 1:696
B39: H | C39: 0.088 | D39: 0.087 | E39: 0.091 | O39: Read 1:696
A41: plate | B41: Platereader well ID | C41: value | D41: sample ID | E41: average blank | F41: blank corrected value | H41: replicate
A42: Read 1:632 | B42: A | C42: 0.089 | D42: blank | E42: =AVERAGE(C42,C50,C58) -> 0.090333333 | F42: =C42-E$42 -> -0.0013333333 | H42: 1
A43: Read 1:632 | B43: B | C43: 0.136 | D43: 98 | F43: =C43-E$42 -> 0.045666667 | H43: 1
A44: Read 1:632 | B44: C | C44: 0.138 | D44: 103 | F44: =C44-E$42 -> 0.047666667 | H44: 1
...

Sheet Read 2
B1: 1 | C1: 2 | D1: 3 | E1: 4 | F1: 5 | G1: 6 | H1: 7 | I1: 8 | J1: 9 | K1: 10 | L1: 11 | M1: 12
A2: A | B2: 0.088 | C2: 0.091 | D2: 0.09 | E2: 0.121 | F2: 0.125 | G2: 0.11 | N2: Read 2:632
A3: B | B3: 0.134 | C3: 0.117 | D3: 0.126 | E3: 0.113 | F3: 0.12 | G3: 0.128 | N3: Read 2:632
A4: C | B4: 0.136 | C4: 0.126 | D4: 0.118 | E4: 0.179 | F4: 0.124 | G4: 0.122 | N4: Read 2:632
A5: D | B5: 0.114 | C5: 0.127 | D5: 0.117 | N5: Read 2:632
A6: E | B6: 0.174 | C6: 0.135 | D6: 0.114 | N6: Read 2:632
A7: F | B7: 0.109 | C7: 0.112 | D7: 0.116 | N7: Read 2:632
A8: G | B8: 0.155 | C8: 0.124 | D8: 0.119 | N8: Read 2:632
A9: H | B9: 0.112 | C9: 0.112 | D9: 0.116 | N9: Read 2:632
B11: 1 | C11: 2 | D11: 3 | E11: 4 | F11: 5 | G11: 6 | H11: 7 | I11: 8 | J11: 9 | K11: 10 | L11: 11 | M11: 12
A12: A | B12: 0.086 | C12: 0.089 | D12: 0.088 | E12: 0.114 | F12: 0.117 | G12: 0.102 | N12: Read 2:649
A13: B | B13: 0.127 | C13: 0.111 | D13: 0.12 | E13: 0.11 | F13: 0.117 | G13: 0.126 | N13: Read 2:649
A14: C | B14: 0.131 | C14: 0.121 | D14: 0.115 | E14: 0.173 | F14: 0.12 | G14: 0.117 | N14: Read 2:649
A15: D | B15: 0.109 | C15: 0.122 | D15: 0.113 | N15: Read 2:649
A16: E | B16: 0.167 | C16: 0.124 | D16: 0.108 | N16: Read 2:649
A17: F | B17: 0.105 | C17: 0.107 | D17: 0.113 | N17: Read 2:649
A18: G | B18: 0.145 | C18: 0.117 | D18: 0.113 | N18: Read 2:649
A19: H | B19: 0.106 | C19: 0.105 | D19: 0.11 | N19: Read 2:649
B21: 1 | C21: 2 | D21: 3 | E21: 4 | F21: 5 | G21: 6 | H21: 7 | I21: 8 | J21: 9 | K21: 10 | L21: 11 | M21: 12
A22: A | B22: 0.085 | C22: 0.088 | D22: 0.087 | E22: 0.148 | F22: 0.153 | G22: 0.127 | N22: Read 2:665
A23: B | B23: 0.184 | C23: 0.144 | D23: 0.17 | E23: 0.147 | F23: 0.172 | G23: 0.173 | N23: Read 2:665
A24: C | B24: 0.2 | C24: 0.163 | D24: 0.161 | E24: 0.218 | F24: 0.177 | G24: 0.168 | N24: Read 2:665
A25: D | B25: 0.147 | C25: 0.185 | D25: 0.157 | N25: Read 2:665
A26: E | B26: 0.195 | C26: 0.143 | D26: 0.133 | N26: Read 2:665
A27: F | B27: 0.132 | C27: 0.144 | D27: 0.142 | N27: Read 2:665
A28: G | B28: 0.2 | C28: 0.167 | D28: 0.15 | N28: Read 2:665
A29: H | B29: 0.132 | C29: 0.134 | D29: 0.143 | N29: Read 2:665
B31: 1 | C31: 2 | D31: 3 | E31: 4 | F31: 5 | G31: 6 | H31: 7 | I31: 8 | J31: 9 | K31: 10 | L31: 11 | M31: 12
A32: A | B32: 0.085 | C32: 0.087 | D32: 0.087 | E32: 0.09 | F32: 0.09 | G32: 0.086 | N32: Read 2:696
A33: B | B33: 0.096 | C33: 0.094 | D33: 0.093 | E33: 0.091 | F33: 0.092 | G33: 0.102 | N33: Read 2:696
A34: C | B34: 0.097 | C34: 0.098 | D34: 0.092 | E34: 0.157 | F34: 0.092 | G34: 0.092 | N34: Read 2:696
A35: D | B35: 0.088 | C35: 0.089 | D35: 0.089 | N35: Read 2:696
A36: E | B36: 0.145 | C36: 0.109 | D36: 0.089 | N36: Read 2:696
A37: F | B37: 0.092 | C37: 0.089 | D37: 0.093 | N37: Read 2:696
A38: G | B38: 0.114 | C38: 0.091 | D38: 0.088 | N38: Read 2:696
A39: H | B39: 0.089 | C39: 0.087 | D39: 0.091 | N39: Read 2:696
A41: plate | B41: Platereader well ID | C41: value | D41: sample ID | E41: average blank | F41: blank corrected value | H41: replicate
A42: Read 1:632 | B42: A | C42: =B2 -> 0.088 | D42: blank | E42: =AVERAGE(C42,C50,C58) -> 0.089666667 | F42: =C42-E$42 -> -0.0016666667 | H42: 1
A43: Read 1:632 | B43: B | C43: =B3 -> 0.134 | D43: 98 | F43: =C43-E$42 -> 0.044333333 | H43: 1
A44: Read 1:632 | B44: C | C44: =B4 -> 0.136 | D44: 103 | F44: =C44-E$42 -> 0.046333333 | H44: 1
...

Sheet Surface Area
A1: surface area estimate
A3: sample ID | B3: SA
A4: blank | B4: NA
A5: 98 | B5: 2.1708393
A6: 103 | B6: 2.01056
A7: 42 | B7: 2.4187131
A8: 50 | B8: 2.2464144
A9: 57 | B9: 2.6249871
A10: 59 | B10: 2.8928691
A11: 79 | B11: 2.3951424
A12: 86 | B12: 2.7593994
A13: 26 | B13: 1.875865
A14: 30 | B14: 2.7232407

Sheet read 1 versus read 2
A3: read | B3: sample ID | C3: cl_a | D3: cl_b | E3: cl_c | F3: cl_d | G3: cl_total
A4: 1 | B4: blank | C4: 0 | D4: 0 | E4: 0 | F4: 0 | G4: 0
A5: 1 | B5: 98 | C5: 0.11986873 | D5: 0.022498475 | E5: 0.092345927 | F5: -0.017819323 | G5: 0.24718608
A6: 1 | B6: 103 | C6: 0.14375109 | D6: 0.029294013 | E6: 0.095175828 | F6: -0.022994839 | G6: 0.28500921
A7: 1 | B7: 42 | C7: 0.088667764 | D7: 0.023097116 | E7: 0.066449861 | F7: -0.0061596309 | G7: 0.18047129
A8: 1 | B8: 50 | C8: 0.091551939 | D8: 0.060127648 | E8: 0.13365504 | F8: -0.053291942 | G8: 0.33311156
A9: 1 | B9: 57 | C9: 0.059081521 | D9: 0.018952871 | E9: 0.045270946 | F9: -0.0095004999 | G9: 0.13013229
A10: 1 | B10: 59 | C10: 0.087971776 | D10: 0.033056328 | E10: 0.087157693 | F10: -0.020879685 | G10: 0.2247205
A11: 1 | B11: 79 | C11: 0.064399702 | D11: 0.013695901 | E11: 0.059649961 | F11: -0.0057161514 | G11: 0.14046458
A12: 1 | B12: 86 | C12: 0.080570867 | D12: 0.0072377067 | E12: 0.060828139 | F12: -0.0054332627 | G12: 0.057635287
A13: 1 | B13: 26 | C13: 0.16391735 | D13: 0.0035596777 | E13: 0.085348826 | F13: -0.021588139 | G13: 0.24008182
A14: 1 | B14: 30 | C14: 0.13949624 | D14: 0.027666248 | E14: 0.088573688 | F14: -0.04221593 | G14: 0.27734617
A15: 2 | B15: blank | C15: 0 | D15: 0 | E15: 0 | F15: 0 | G15: 0
A16: 2 | B16: 98 | C16: 0.14473058 | D16: 0.0086393412 | E16: 0.087080619 | F16: -0.018819527 | G16: 0.25327958
A17: 2 | B17: 103 | C17: 0.1735309 | D17: 0.01021431 | E17: 0.090418912 | F17: -0.023413973 | G17: 0.29059479
A18: 2 | B18: 42 | C18: 0.12856779 | D18: -0.00030244802 | E18: 0.061146981 | F18: -0.0067346212 | G18: 0.19117732
A19: 2 | B19: 50 | C19: 0.1063314 | D19: 0.054932717 | E19: 0.12793335 | F19: -0.056016245 | G19: 0.33932323
A20: 2 | B20: 57 | C20: 0.079735542 | D20: 0.0043266701 | E20: 0.043680432 | F20: -0.0098002791 | G20: 0.13431199
A21: 2 | B21: 59 | C21: 0.1150215 | D21: 0.013778009 | E21: 0.080384667 | F21: -0.019272479 | G21: 0.2234665
A22: 2 | B22: 79 | C22: 0.083055288 | D22: 0.0033001795 | E22: 0.055443089 | F22: -0.0065668955 | G22: 0.14488795
A23: 2 | B23: 86 | C23: 0.080570867 | D23: 0.0072377067 | E23: 0.060828139 | F23: -0.0054332627 | G23: 0.058271614
A24: 2 | B24: 26 | C24: 0.16366669 | D24: 0.0086011536 | E24: 0.076058767 | F24: -0.0230431 | G24: 0.23919741
A25: 2 | B25: 30 | C25: 0.13803501 | D25: 0.028106252 | E25: 0.095792227 | F25: -0.045898372 | G25: 0.2971881
